<mujoco model="intention">
  <compiler angle="radian" meshdir="meshes" autolimits="true"/>

  <option cone="pyramidal" impratio="100"/>

  <statistic meansize="0.169822"/>

  <default>
    <geom condim="3" friction="1.1 0.005 0.0001" solimp="1.2 1.1" solref="-1000 -80" mass="0"/>
    <joint stiffness="0.0" damping="0.1" armature="0.013122" frictionloss="0.48"/>
  </default>

  <asset>
    <texture name="texplane" type="2d" builtin="checker" rgb1=".12 .14 .44" rgb2=".37 .55 1" width="100" height="100"/>
    <material name="MatPlane" reflectance="0.5" texture="texplane" texrepeat="1 1" texuniform="true"></material>
    
    <mesh name="body" file="body.stl" scale="0.001 0.001 0.001"/>
    <mesh name="rear" file="rear.stl" scale="0.001 0.001 0.001"/>
    <mesh name="l0r" file="l0r.stl" scale="0.001 0.001 0.001"/>
    <mesh name="l1r" file="l1r.stl" scale="0.001 0.001 0.001"/>
    <mesh name="l2r" file="l2r.stl" scale="0.001 0.001 0.001"/>
    <mesh name="l0l" file="l0l.stl" scale="0.001 0.001 0.001"/>
    <mesh name="l1lf" file="l1lf.stl" scale="0.001 0.001 0.001"/>
    <mesh name="l2l" file="l2l.stl" scale="0.001 0.001 0.001"/>
  </asset>

  <worldbody>
    <geom name="floor" pos="0 0 0" condim="3" material="MatPlane" size="100 100 0.125" rgba="0.8 0.9 0.8 1" type="plane"/>
    <light cutoff="100" diffuse="1 1 1" dir="-0 0 -1.3" directional="true" exponent="1" pos="0 0 1.3" specular=".1 .1 .1" castshadow="false"/>
    <light name="spotlight" mode="targetbodycom" target="trunk" pos="0 -1 2"/>

    <body name="trunk" pos="0 0 0">
      <camera name="track" mode="trackcom" pos="0 -2 0" xyaxes="1 0 0 0 0 1"/>
      <freejoint/>

      <inertial mass="5.423" pos="0.0 0.0 0.0" diaginertia="0.1946 0.4899 0.6228"/>

      <geom type="mesh" contype="0" conaffinity="0" group="1" density="0" rgba="0.6 0.6 0.6 1" mesh="body"/>
      <geom size="0.11 0.07 0.045" pos="0.025 0 0" type="box" rgba="0.6 0.6 0.6 1"/>
      <geom name="trunk_1" size="0.05 0.11" pos="0.025 0.064 0" quat="0.707388 0 0.706825 0" type="cylinder" rgba="0.6 0.6 0.6 1"/>
      <geom name="trunk_2" size="0.05 0.11" pos="0.025 -0.064 0" quat="0.707388 0 0.706825 0" type="cylinder" rgba="0.6 0.6 0.6 1"/>

      <body name="rear" pos="-0.141 -0.0395 0" quat="-9.37064e-07 -0.706262 0.707951 9.39306e-07">
        <inertial pos="-0.038 0.075 0" quat="0.5 0.5 -0.5 0.5" mass="1.337" diaginertia="0.1561 0.09 0.0835" />
        <geom type="mesh" contype="0" conaffinity="0" group="1" rgba="0.6 0.6 0.6 1" mesh="rear" />
        <geom size="0.1 0.025 0.05" pos="-0.04 0.08 0" type="box" rgba="0.6 0.6 0.6 0" />
        <body name="rl_l0" pos="-0.1025 0.10765 0" quat="0.707388 0 0 0.706825">
          <inertial pos="0.0557 -0.016 0" quat="0.5 0.5 0.5 0.5" mass="0.645" diaginertia="0.0093 0.0065 0.0052" />
          <joint name="RL_hip_joint" pos="0 0 0" axis="1 0 0" limited="true" range="-1.57 1.57" />
          <geom type="mesh" contype="0" conaffinity="0" group="1" rgba="0.6 0.6 0.6 1" mesh="l0l" />
          <body name="rl_l1" pos="0.0555 0.0125 0" quat="9.38559e-07 0.707388 0.706825 9.37812e-07">
            <inertial pos="0.031 0.016 0" quat="0.707107 0.707107 0 0" mass="0.827" diaginertia="0.033 0.0286 0.0077" />
            <joint name="RL_thigh_joint" pos="0 0 0" axis="1 0 0" limited="true" range="-1.57 1.57" />
            <geom type="mesh" contype="0" conaffinity="0" group="1" rgba="1 0.41 0 1" mesh="l1lf" />
            <geom size="0.05 0.04" quat="0.707388 0 0.706825 0" type="cylinder" rgba="1 0.41 0 0" />
              <body name="rl_l2" pos="0.0584 0.2 0" quat="0.116034 -0.993245 0 0">
                <inertial pos="0.001 0.104 -0.003" quat="0.707107 0.707107 0 0" mass="0.118" diaginertia="0.0213 0.0212 0.0002" />
                <joint name="RL_calf_joint" pos="0 0 0" axis="1 0 0" limited="true" range="0 2.53" />
                <geom type="mesh" contype="0" conaffinity="0" group="1" rgba="0.6 0.6 0.6 1" mesh="l2l" />
                <geom size="0.01 0.03125" pos="0 -0.01 0.0055" quat="0.796084 -0.605186 0 0" type="cylinder" rgba="0.6 0.6 0.6 0" />
                <geom name="RL_calf" size="0.015 0.1" pos="0 0.1 0.005" quat="0.670968 -0.741065 0.0185305 -0.0167777" type="cylinder" rgba="0.6 0.6 0.6 0" />
                <geom size="0.021" pos="0.0054 0.2 0" contype="0" conaffinity="0" group="1" rgba="0.1 0.1 0.1 1" />
                <geom name="RL_foot" size="0.02" pos="0.0054 0.2 0" rgba="0.1 0.1 0.1 1" />
              </body>
          </body>
        </body>
        <body name="rr_l0" pos="0.0255 0.10725 0" quat="0.707388 0 0 0.706825">
          <inertial pos="0.0557 -0.016 0" quat="0.5 0.5 0.5 0.5" mass="0.645" diaginertia="0.0093 0.0065 0.0052" />
          <joint name="RR_hip_joint" pos="0 0 0" axis="1 0 0" limited="true" range="-1.57 1.57" />
          <geom type="mesh" contype="0" conaffinity="0" group="1" rgba="0.6 0.6 0.6 1" mesh="l0r" />
          <body name="rr_l1" pos="0.0555 -0.0125 0" quat="9.38559e-07 0.707388 -0.706825 -9.37812e-07">
            <inertial pos="0.031 0.016 0" quat="0.707107 0.707107 0 0" mass="0.827" diaginertia="0.033 0.0286 0.0077" />
            <joint name="RR_thigh_joint" pos="0 0 0" axis="1 0 0" limited="true" range="-1.57 1.57" />
            <geom type="mesh" contype="0" conaffinity="0" group="1" rgba="1 0.41 0 1" mesh="l1r" />
            <geom size="0.05 0.04" quat="0.707388 0 0.706825 0" type="cylinder" rgba="1 0.41 0 0" />
            <body name="rr_l2" pos="0.0584 -0.2 0" quat="0.116034 0.993245 0 0">
              <inertial pos="0.001 0.104 -0.003" quat="0.707107 0.707107 0 0" mass="0.118" diaginertia="0.0213 0.0212 0.0002" />
              <joint name="RR_calf_joint" pos="0 0 0" axis="1 0 0" limited="true" range="-2.53 0" />
              <geom type="mesh" contype="0" conaffinity="0" group="1" rgba="0.6 0.6 0.6 1" mesh="l2r" />
              <geom size="0.01 0.03125" pos="0 0.01 0.0055" quat="0.796084 0.605186 0 0" type="cylinder" rgba="0.6 0.6 0.6 0" />
              <geom name="RR_calf" size="0.015 0.1" pos="0 -0.1 0.005" quat="0.670968 0.741065 0.0185305 0.0167777" type="cylinder" rgba="0.6 0.6 0.6 0" />
              <geom size="0.021" pos="0.0054 -0.2 0" contype="0" conaffinity="0" group="1" rgba="0.1 0.1 0.1 1" />
              <geom name="RR_foot" size="0.02" pos="0.0054 -0.2 0" rgba="0.1 0.1 0.1 1" />
            </body>
          </body>
        </body>
      </body>
      <body name="fr_l0" pos="0.1375 -0.064 0">
        <inertial pos="0.0557 -0.016 0" quat="0.5 0.5 0.5 0.5" mass="0.645" diaginertia="0.0093 0.0065 0.0052" />
        <joint name="FR_hip_joint" pos="0 0 0" axis="1 0 0" limited="true" range="-1.57 1.57" />
        <geom type="mesh" contype="0" conaffinity="0" group="1" rgba="0.6 0.6 0.6 1" mesh="l0r" />
        <body name="fr_l1" pos="0.0555 -0.0125 0" quat="0.707388 0 0 -0.706825">
          <inertial pos="0.031 0.016 0" quat="0.707107 0.707107 0 0" mass="0.827" diaginertia="0.033 0.0286 0.0077" />
          <joint name="FR_thigh_joint" pos="0 0 0" axis="1 0 0" limited="true" range="-1.57 1.57" />
          <geom type="mesh" contype="0" conaffinity="0" group="1" rgba="1 0.41 0 1" mesh="l1r" />
          <geom size="0.05 0.04" quat="0.707388 0 0.706825 0" type="cylinder" rgba="1 0.41 0 0" />
          <body name="fr_l2" pos="0.0584 -0.2 0" quat="0.116034 0.993245 0 0">
            <inertial pos="0.001 0.104 -0.003" quat="0.707107 0.707107 0 0" mass="0.118" diaginertia="0.0213 0.0212 0.0002" />
            <joint name="FR_calf_joint" pos="0 0 0" axis="1 0 0" limited="true" range="-2.53 0" />
            <geom type="mesh" contype="0" conaffinity="0" group="1" rgba="0.6 0.6 0.6 1" mesh="l2r" />
            <geom size="0.01 0.03125" pos="0 0.01 0.0055" quat="0.796084 0.605186 0 0" type="cylinder" rgba="0.6 0.6 0.6 0" />
            <geom name="FR_calf" size="0.015 0.1" pos="0 -0.1 0.005" quat="0.670968 0.741065 0.0185305 0.0167777" type="cylinder" rgba="1 0 0 0" />
            <geom size="0.021" pos="0.0054 -0.2 0" contype="0" conaffinity="0" group="1" rgba="0.1 0.1 0.1 1" />
            <geom name="FR_foot" size="0.02" pos="0.0054 -0.2 0" rgba="0.1 0.1 0.1 1" />
          </body>
        </body>
      </body>
      <body name="fl_l0" pos="0.1375 0.064 0">
        <inertial pos="0.0557 -0.016 0" quat="0.5 0.5 0.5 0.5" mass="0.645" diaginertia="0.0093 0.0065 0.0052" />
        <joint name="FL_hip_joint" pos="0 0 0" axis="1 0 0" limited="true" range="-1.57 1.57" />
        <geom type="mesh" contype="0" conaffinity="0" group="1" rgba="0.6 0.6 0.6 1" mesh="l0l" />
        <body name="fl_l1" pos="0.0555 0.0125 0" quat="0.707388 0 0 0.706825">
          <inertial pos="0.031 0.016 0" quat="0.707107 0.707107 0 0" mass="0.827" diaginertia="0.033 0.0286 0.0077" />
          <joint name="FL_thigh_joint" pos="0 0 0" axis="1 0 0" limited="true" range="-1.57 1.57" />
          <geom type="mesh" contype="0" conaffinity="0" group="1" rgba="1 0.41 0 1" mesh="l1lf" />
          <geom size="0.05 0.04" quat="0.707388 0 0.706825 0" type="cylinder" rgba="1 0.41 0 0" />
          <body name="fl_l2" pos="0.0584 0.2 0" quat="0.116034 -0.993245 0 0">
            <inertial pos="0.001 0.104 -0.003" quat="0.707107 0.707107 0 0" mass="0.118" diaginertia="0.0213 0.0212 0.0002" />
            <joint name="FL_calf_joint" pos="0 0 0" axis="1 0 0" limited="true" range="0 2.53" />
            <geom type="mesh" contype="0" conaffinity="0" group="1" rgba="0.6 0.6 0.6 1" mesh="l2l" />
            <geom size="0.01 0.03125" pos="0 -0.01 0.0055" quat="0.796084 -0.605186 0 0" type="cylinder" rgba="0.6 0.6 0.6 0" />
            <geom name="FL_calf" size="0.015 0.1" pos="0 0.1 0.005" quat="0.670968 -0.741065 0.0185305 -0.0167777" type="cylinder" rgba="0.6 0.6 0.6 0" />
            <geom size="0.021" pos="0.0054 0.2 0" contype="0" conaffinity="0" group="1" rgba="0.1 0.1 0.1 1" />
            <geom name="FL_foot" size="0.02" pos="0.0054 0.2 0" rgba="0.1 0.1 0.1 1" />
          </body>
        </body>
      </body>
    </body>
  </worldbody>
  
  <actuator>
    <motor name="RL_hip" joint="RL_hip_joint" ctrllimited="true" ctrlrange="-16 16"></motor>
    <motor name="RL_thigh" joint="RL_thigh_joint" ctrllimited="true" ctrlrange="-16 16"></motor>
    <motor name="RL_calf" joint="RL_calf_joint" ctrllimited="true" ctrlrange="-16 16"></motor>
    <motor name="RR_hip" joint="RR_hip_joint" ctrllimited="true" ctrlrange="-16 16"></motor>
    <motor name="RR_thigh" joint="RR_thigh_joint" ctrllimited="true" ctrlrange="-16 16"></motor>
    <motor name="RR_calf" joint="RR_calf_joint" ctrllimited="true" ctrlrange="-16 16"></motor>
    <motor name="FR_hip" joint="FR_hip_joint" ctrllimited="true" ctrlrange="-16 16"></motor>
    <motor name="FR_thigh" joint="FR_thigh_joint" ctrllimited="true" ctrlrange="-16 16"></motor>
    <motor name="FR_calf" joint="FR_calf_joint" ctrllimited="true" ctrlrange="-16 16"></motor>
    <motor name="FL_hip" joint="FL_hip_joint" ctrllimited="true" ctrlrange="-16 16"></motor>
    <motor name="FL_thigh" joint="FL_thigh_joint" ctrllimited="true" ctrlrange="-16 16"></motor>
    <motor name="FL_calf" joint="FL_calf_joint" ctrllimited="true" ctrlrange="-16 16"></motor>
  </actuator>

  <keyframe>
    <key name="home" qpos="0 0 0.316 1 0 0 0 -0.1 -1.0 1.5 0.1 1.0 -1.5 -0.1 0.8 -1.5 0.1 -0.8 1.5"/>
  </keyframe>
</mujoco>
