<mujoco model="snake">
  <compiler angle="radian" autolimits="true"/>

  <option cone="pyramidal" impratio="100"/>

  <default>
    <geom solref="-1000 -80"/>
    <joint stiffness="0.0" armature="0.03"/>
    <motor ctrllimited="true" ctrlrange="-7.0 7.0"/>
  </default>

  <asset>
    <texture name="texplane" type="2d" builtin="checker" rgb1=".12 .14 .44" rgb2=".37 .55 1" width="100" height="100"/>
    <material name="MatPlane" reflectance="0.5" texture="texplane" texrepeat="1 1" texuniform="true"></material>
  </asset>

  <worldbody>
    <geom name="floor" pos="0 0 0" condim="3" material="MatPlane" size="100 100 0.125" rgba="0.8 0.9 0.8 1" type="plane"/>

    <light cutoff="100" diffuse="1 1 1" dir="-0 0 -1.3" directional="true" exponent="1" pos="0 0 1.3" specular=".1 .1 .1" castshadow="false"/>
    <light name="spotlight" mode="targetbodycom" target="trunk" pos="0 -1 2"/>

    <body name="trunk" pos="0 0 0">
      <camera name="track" mode="trackcom" pos="0 -2 0" xyaxes="1 0 0 0 0 1"/>
      <freejoint/>

      <inertial pos="0 0 0" mass="0.103" diaginertia="5.4796e-05 5.4796e-05 3.4814e-05"/>

      <geom size="0.026 0.0165" pos="-0.0183 0 0" quat="0.707107 0 -0.707107 0" type="cylinder" rgba="0.3 0.1 0.1 1"/>
      <geom size="0.01 0.001" pos="-0.001 0 0.01" quat="0.707107 0 -0.707107 0" type="cylinder" rgba="0.0 0.0 0.0 1"/>

      <body name="SA001__MoJo__OUTPUT_BODY" pos="-0.0366 0 0" quat="0.707107 0 -0.707107 0">
        <inertial pos="0 0 0.03195" mass="0.206" diaginertia="0.000319877 0.000319877 6.9628e-05"/>
        <joint name="SA001__MoJo" pos="0 0 0" axis="0 1 0" range="-1.57 1.57" damping="0.1" frictionloss="0.2"/>
        <geom size="0.026 0.0165" pos="0 0 0.0183" type="cylinder" rgba="0.82 0.06 0.06 1"/>
        <geom size="0.026 0.0165" pos="0 0 0.0456" quat="0.707123 0 0 -0.70709" type="cylinder" rgba="0.82 0.06 0.06 1"/>
        <body name="SA002__MoJo__OUTPUT_BODY" pos="0 0 0.0639" quat="0.707123 0 0 -0.70709">
          <inertial pos="0 0 0.03195" mass="0.206" diaginertia="0.000319877 0.000319877 6.9628e-05"/>
          <joint name="SA002__MoJo" pos="0 0 0" axis="0 1 0" range="-1.57 1.57" damping="0.1" frictionloss="0.2"/>
          <geom size="0.026 0.0165" pos="0 0 0.0183" type="cylinder" rgba="0.82 0.06 0.06 1"/>
          <geom size="0.026 0.0165" pos="0 0 0.0456" quat="0.707123 0 0 -0.70709" type="cylinder" rgba="0.82 0.06 0.06 1"/>
          <body name="SA003__MoJo__OUTPUT_BODY" pos="0 0 0.0639" quat="0.707123 0 0 -0.70709">
            <inertial pos="0 0 0.03195" mass="0.206" diaginertia="0.000319877 0.000319877 6.9628e-05"/>
            <joint name="SA003__MoJo" pos="0 0 0" axis="0 1 0" range="-1.57 1.57" damping="0.1" frictionloss="0.2"/>
            <geom size="0.026 0.0165" pos="0 0 0.0183" type="cylinder" rgba="0.82 0.06 0.06 1"/>
            <geom size="0.026 0.0165" pos="0 0 0.0456" quat="0.707123 0 0 -0.70709" type="cylinder" rgba="0.82 0.06 0.06 1"/>
            <body name="SA004__MoJo__OUTPUT_BODY" pos="0 0 0.0639" quat="0.707123 0 0 -0.70709">
              <inertial pos="0 0 0.03195" mass="0.206" diaginertia="0.000319877 0.000319877 6.9628e-05"/>
              <joint name="SA004__MoJo" pos="0 0 0" axis="0 1 0" range="-1.57 1.57" damping="0.1" frictionloss="0.2"/>
              <geom size="0.026 0.0165" pos="0 0 0.0183" type="cylinder" rgba="0.82 0.06 0.06 1"/>
              <geom size="0.026 0.0165" pos="0 0 0.0456" quat="0.707123 0 0 -0.70709" type="cylinder" rgba="0.82 0.06 0.06 1"/>
              <body name="SA005__MoJo__OUTPUT_BODY" pos="0 0 0.0639" quat="0.707123 0 0 -0.70709">
                <inertial pos="0 0 0.03195" mass="0.206" diaginertia="0.000319877 0.000319877 6.9628e-05"/>
                <joint name="SA005__MoJo" pos="0 0 0" axis="0 1 0" range="-1.57 1.57" damping="0.1" frictionloss="0.2"/>
                <geom size="0.026 0.0165" pos="0 0 0.0183" type="cylinder" rgba="0.82 0.06 0.06 1"/>
                <geom size="0.026 0.0165" pos="0 0 0.0456" quat="0.707123 0 0 -0.70709" type="cylinder" rgba="0.82 0.06 0.06 1"/>
                <body name="SA006__MoJo__OUTPUT_BODY" pos="0 0 0.0639" quat="0.707123 0 0 -0.70709">
                  <inertial pos="0 0 0.03195" mass="0.206" diaginertia="0.000319877 0.000319877 6.9628e-05"/>
                  <joint name="SA006__MoJo" pos="0 0 0" axis="0 1 0" range="-1.57 1.57" damping="0.1" frictionloss="0.2"/>
                  <geom size="0.026 0.0165" pos="0 0 0.0183" type="cylinder" rgba="0.82 0.06 0.06 1"/>
                  <geom size="0.026 0.0165" pos="0 0 0.0456" quat="0.707123 0 0 -0.70709" type="cylinder" rgba="0.82 0.06 0.06 1"/>
                  <body name="SA007__MoJo__OUTPUT_BODY" pos="0 0 0.0639" quat="0.707123 0 0 -0.70709">
                    <inertial pos="0 0 0.03195" mass="0.206" diaginertia="0.000319877 0.000319877 6.9628e-05"/>
                    <joint name="SA007__MoJo" pos="0 0 0" axis="0 1 0" range="-1.57 1.57" damping="0.1" frictionloss="0.2"/>
                    <geom size="0.026 0.0165" pos="0 0 0.0183" type="cylinder" rgba="0.82 0.06 0.06 1"/>
                    <geom size="0.026 0.0165" pos="0 0 0.0456" quat="0.707123 0 0 -0.70709" type="cylinder" rgba="0.82 0.06 0.06 1"/>
                    <body name="SA008__MoJo__OUTPUT_BODY" pos="0 0 0.0639" quat="0.707123 0 0 -0.70709">
                      <inertial pos="0 0 0.03195" mass="0.206" diaginertia="0.000319877 0.000319877 6.9628e-05"/>
                      <joint name="SA008__MoJo" pos="0 0 0" axis="0 1 0" range="-1.57 1.57" damping="0.1" frictionloss="0.2"/>
                      <geom size="0.026 0.0165" pos="0 0 0.0183" type="cylinder" rgba="0.82 0.06 0.06 1"/>
                      <geom size="0.026 0.0165" pos="0 0 0.0456" quat="0.707123 0 0 -0.70709" type="cylinder" rgba="0.82 0.06 0.06 1"/>
                      <body name="SA009__MoJo__OUTPUT_BODY" pos="0 0 0.0639" quat="0.707123 0 0 -0.70709">
                        <inertial pos="0 0 0.03195" mass="0.206" diaginertia="0.000319877 0.000319877 6.9628e-05"/>
                        <joint name="SA009__MoJo" pos="0 0 0" axis="0 1 0" range="-1.57 1.57" damping="0.1" frictionloss="0.2"/>
                        <geom size="0.026 0.0165" pos="0 0 0.0183" type="cylinder" rgba="0.82 0.06 0.06 1"/>
                        <geom size="0.026 0.0165" pos="0 0 0.0456" quat="0.707123 0 0 -0.70709" type="cylinder" rgba="0.82 0.06 0.06 1"/>
                        <body name="SA010__MoJo__OUTPUT_BODY" pos="0 0 0.0639" quat="0.707123 0 0 -0.70709">
                          <inertial pos="0 0 0.03195" mass="0.206" diaginertia="0.000319877 0.000319877 6.9628e-05"/>
                          <joint name="SA010__MoJo" pos="0 0 0" axis="0 1 0" range="-1.57 1.57" damping="0.1" frictionloss="0.2"/>
                          <geom size="0.026 0.0165" pos="0 0 0.0183" type="cylinder" rgba="0.82 0.06 0.06 1"/>
                          <geom size="0.026 0.0165" pos="0 0 0.0456" quat="0.707123 0 0 -0.70709" type="cylinder" rgba="0.82 0.06 0.06 1"/>
                          <body name="SA011__MoJo__OUTPUT_BODY" pos="0 0 0.0639" quat="0.707123 0 0 -0.70709">
                            <inertial pos="0 0 0.03195" mass="0.206" diaginertia="0.000319877 0.000319877 6.9628e-05"/>
                            <joint name="SA011__MoJo" pos="0 0 0" axis="0 1 0" range="-1.57 1.57" damping="0.1" frictionloss="0.2"/>
                            <geom size="0.026 0.0165" pos="0 0 0.0183" type="cylinder" rgba="0.82 0.06 0.06 1"/>
                            <geom size="0.026 0.0165" pos="0 0 0.0456" quat="0.707123 0 0 -0.70709" type="cylinder" rgba="0.82 0.06 0.06 1"/>
                            <body name="SA012__MoJo__OUTPUT_BODY" pos="0 0 0.0639" quat="0.707123 0 0 -0.70709">
                              <inertial pos="0 0 0.03195" mass="0.206" diaginertia="0.000319877 0.000319877 6.9628e-05"/>
                              <joint name="SA012__MoJo" pos="0 0 0" axis="0 1 0" range="-1.57 1.57" damping="0.1" frictionloss="0.2"/>
                              <geom size="0.026 0.0165" pos="0 0 0.0183" type="cylinder" rgba="0.82 0.06 0.06 1"/>
                              <geom size="0.026 0.0165" pos="0 0 0.0456" quat="0.707123 0 0 -0.70709" type="cylinder" rgba="0.82 0.06 0.06 1"/>
                              <body name="SA013__MoJo__OUTPUT_BODY" pos="0 0 0.0639" quat="0.707123 0 0 -0.70709">
                                <inertial pos="0 0 0.03195" mass="0.206" diaginertia="0.000319877 0.000319877 6.9628e-05"/>
                                <joint name="SA013__MoJo" pos="0 0 0" axis="0 1 0" range="-1.57 1.57" damping="0.1" frictionloss="0.2"/>
                                <geom size="0.026 0.0165" pos="0 0 0.0183" type="cylinder" rgba="0.82 0.06 0.06 1"/>
                                <geom size="0.026 0.0165" pos="0 0 0.0456" quat="0.707123 0 0 -0.70709" type="cylinder" rgba="0.82 0.06 0.06 1"/>
                                <body name="SA014__MoJo__OUTPUT_BODY" pos="0 0 0.0639" quat="0.707123 0 0 -0.70709">
                                  <inertial pos="0 0 0.03195" mass="0.206" diaginertia="0.000319877 0.000319877 6.9628e-05"/>
                                  <joint name="SA014__MoJo" pos="0 0 0" axis="0 1 0" range="-1.57 1.57" damping="0.1" frictionloss="0.2"/>
                                  <geom size="0.026 0.0165" pos="0 0 0.0183" type="cylinder" rgba="0.82 0.06 0.06 1"/>
                                  <geom size="0.026 0.0165" pos="0 0 0.0456" quat="0.707123 0 0 -0.70709" type="cylinder" rgba="0.82 0.06 0.06 1"/>
                                  <body name="SA015__MoJo__OUTPUT_BODY" pos="0 0 0.0639" quat="0.707123 0 0 -0.70709">
                                    <inertial pos="0 0 0.03195" mass="0.206" diaginertia="0.000319877 0.000319877 6.9628e-05"/>
                                    <joint name="SA015__MoJo" pos="0 0 0" axis="0 1 0" range="-1.57 1.57" damping="0.1" frictionloss="0.2"/>
                                    <geom size="0.026 0.0165" pos="0 0 0.0183" type="cylinder" rgba="0.82 0.06 0.06 1"/>
                                    <geom size="0.026 0.0165" pos="0 0 0.0456" quat="0.707123 0 0 -0.70709" type="cylinder" rgba="0.82 0.06 0.06 1"/>
                                    <body name="SA016__MoJo__OUTPUT_BODY" pos="0 0 0.0639" quat="0.707123 0 0 -0.70709">
                                      <inertial pos="0 0 0" mass="0.103" diaginertia="5.4796e-05 5.4796e-05 3.4814e-05"/>
                                      <joint name="SA016__MoJo" pos="0 0 0" axis="0 1 0" range="-1.57 1.57" damping="0.1" frictionloss="0.2"/>
                                      <geom name="dummy_foot" size="0.026 0.0165" pos="0 0 0.0183" type="cylinder" rgba="0.5 0.5 0.5 1"/>
                                    </body>
                                  </body>
                                </body>
                              </body>
                            </body>
                          </body>
                        </body>
                      </body>
                    </body>
                  </body>
                </body>
              </body>
            </body>
          </body>
        </body>
      </body>
    </body>
  </worldbody>

  <actuator>
    <motor name="actuator_1" joint="SA001__MoJo"></motor>
    <motor name="actuator_2" joint="SA002__MoJo"></motor>
    <motor name="actuator_3" joint="SA003__MoJo"></motor>
    <motor name="actuator_4" joint="SA004__MoJo"></motor>
    <motor name="actuator_5" joint="SA005__MoJo"></motor>
    <motor name="actuator_6" joint="SA006__MoJo"></motor>
    <motor name="actuator_7" joint="SA007__MoJo"></motor>
    <motor name="actuator_8" joint="SA008__MoJo"></motor>
    <motor name="actuator_9" joint="SA009__MoJo"></motor>
    <motor name="actuator_10" joint="SA010__MoJo"></motor>
    <motor name="actuator_11" joint="SA011__MoJo"></motor>
    <motor name="actuator_12" joint="SA012__MoJo"></motor>
    <motor name="actuator_13" joint="SA013__MoJo"></motor>
    <motor name="actuator_14" joint="SA014__MoJo"></motor>
    <motor name="actuator_15" joint="SA015__MoJo"></motor>
    <motor name="actuator_16" joint="SA016__MoJo"></motor>
  </actuator>

  <keyframe>
    <key name="home" qpos="0 0 0.026 1 0 0 0 0.0 0.0 0.0 0.0 0.0 0.0 0.0 0.0 0.0 0.0 0.0 0.0 0.0 0.0 0.0 0.0"/>
  </keyframe>
</mujoco>
